2019-09-20 16:51:50,472 INFO: Microblog startup [in /home/mike/Desktop/microblog-0.15/app/__init__.py:80]
2019-09-20 16:52:00,114 ERROR: Exception on /explore [GET] [in /home/mike/Desktop/microblog-0.15/venv/lib/python3.6/site-packages/flask/app.py:1761]
Traceback (most recent call last):
  File "/home/mike/Desktop/microblog-0.15/venv/lib/python3.6/site-packages/flask/app.py", line 2292, in wsgi_app
    response = self.full_dispatch_request()
  File "/home/mike/Desktop/microblog-0.15/venv/lib/python3.6/site-packages/flask/app.py", line 1815, in full_dispatch_request
    rv = self.handle_user_exception(e)
  File "/home/mike/Desktop/microblog-0.15/venv/lib/python3.6/site-packages/flask/app.py", line 1718, in handle_user_exception
    reraise(exc_type, exc_value, tb)
  File "/home/mike/Desktop/microblog-0.15/venv/lib/python3.6/site-packages/flask/_compat.py", line 35, in reraise
    raise value
  File "/home/mike/Desktop/microblog-0.15/venv/lib/python3.6/site-packages/flask/app.py", line 1813, in full_dispatch_request
    rv = self.dispatch_request()
  File "/home/mike/Desktop/microblog-0.15/venv/lib/python3.6/site-packages/flask/app.py", line 1799, in dispatch_request
    return self.view_functions[rule.endpoint](**req.view_args)
  File "/home/mike/Desktop/microblog-0.15/venv/lib/python3.6/site-packages/flask_login/utils.py", line 228, in decorated_view
    return func(*args, **kwargs)
  File "/home/mike/Desktop/microblog-0.15/app/main/routes.py", line 56, in explore
    page, current_app.config['25'], False)@bp.route('/search')
KeyError: '25'
2019-09-20 16:52:00,857 ERROR: Exception on /explore [GET] [in /home/mike/Desktop/microblog-0.15/venv/lib/python3.6/site-packages/flask/app.py:1761]
Traceback (most recent call last):
  File "/home/mike/Desktop/microblog-0.15/venv/lib/python3.6/site-packages/flask/app.py", line 2292, in wsgi_app
    response = self.full_dispatch_request()
  File "/home/mike/Desktop/microblog-0.15/venv/lib/python3.6/site-packages/flask/app.py", line 1815, in full_dispatch_request
    rv = self.handle_user_exception(e)
  File "/home/mike/Desktop/microblog-0.15/venv/lib/python3.6/site-packages/flask/app.py", line 1718, in handle_user_exception
    reraise(exc_type, exc_value, tb)
  File "/home/mike/Desktop/microblog-0.15/venv/lib/python3.6/site-packages/flask/_compat.py", line 35, in reraise
    raise value
  File "/home/mike/Desktop/microblog-0.15/venv/lib/python3.6/site-packages/flask/app.py", line 1813, in full_dispatch_request
    rv = self.dispatch_request()
  File "/home/mike/Desktop/microblog-0.15/venv/lib/python3.6/site-packages/flask/app.py", line 1799, in dispatch_request
    return self.view_functions[rule.endpoint](**req.view_args)
  File "/home/mike/Desktop/microblog-0.15/venv/lib/python3.6/site-packages/flask_login/utils.py", line 228, in decorated_view
    return func(*args, **kwargs)
  File "/home/mike/Desktop/microblog-0.15/app/main/routes.py", line 56, in explore
    page, current_app.config['25'], False)@bp.route('/search')
KeyError: '25'
2019-09-20 16:52:01,334 ERROR: Exception on /index [GET] [in /home/mike/Desktop/microblog-0.15/venv/lib/python3.6/site-packages/flask/app.py:1761]
Traceback (most recent call last):
  File "/home/mike/Desktop/microblog-0.15/venv/lib/python3.6/site-packages/flask/app.py", line 2292, in wsgi_app
    response = self.full_dispatch_request()
  File "/home/mike/Desktop/microblog-0.15/venv/lib/python3.6/site-packages/flask/app.py", line 1815, in full_dispatch_request
    rv = self.handle_user_exception(e)
  File "/home/mike/Desktop/microblog-0.15/venv/lib/python3.6/site-packages/flask/app.py", line 1718, in handle_user_exception
    reraise(exc_type, exc_value, tb)
  File "/home/mike/Desktop/microblog-0.15/venv/lib/python3.6/site-packages/flask/_compat.py", line 35, in reraise
    raise value
  File "/home/mike/Desktop/microblog-0.15/venv/lib/python3.6/site-packages/flask/app.py", line 1813, in full_dispatch_request
    rv = self.dispatch_request()
  File "/home/mike/Desktop/microblog-0.15/venv/lib/python3.6/site-packages/flask/app.py", line 1799, in dispatch_request
    return self.view_functions[rule.endpoint](**req.view_args)
  File "/home/mike/Desktop/microblog-0.15/venv/lib/python3.6/site-packages/flask_login/utils.py", line 228, in decorated_view
    return func(*args, **kwargs)
  File "/home/mike/Desktop/microblog-0.15/app/main/routes.py", line 41, in index
    page, current_app.config['25'], False)
KeyError: '25'
2019-09-20 16:52:02,067 ERROR: Exception on /index [GET] [in /home/mike/Desktop/microblog-0.15/venv/lib/python3.6/site-packages/flask/app.py:1761]
Traceback (most recent call last):
  File "/home/mike/Desktop/microblog-0.15/venv/lib/python3.6/site-packages/flask/app.py", line 2292, in wsgi_app
    response = self.full_dispatch_request()
  File "/home/mike/Desktop/microblog-0.15/venv/lib/python3.6/site-packages/flask/app.py", line 1815, in full_dispatch_request
    rv = self.handle_user_exception(e)
  File "/home/mike/Desktop/microblog-0.15/venv/lib/python3.6/site-packages/flask/app.py", line 1718, in handle_user_exception
    reraise(exc_type, exc_value, tb)
  File "/home/mike/Desktop/microblog-0.15/venv/lib/python3.6/site-packages/flask/_compat.py", line 35, in reraise
    raise value
  File "/home/mike/Desktop/microblog-0.15/venv/lib/python3.6/site-packages/flask/app.py", line 1813, in full_dispatch_request
    rv = self.dispatch_request()
  File "/home/mike/Desktop/microblog-0.15/venv/lib/python3.6/site-packages/flask/app.py", line 1799, in dispatch_request
    return self.view_functions[rule.endpoint](**req.view_args)
  File "/home/mike/Desktop/microblog-0.15/venv/lib/python3.6/site-packages/flask_login/utils.py", line 228, in decorated_view
    return func(*args, **kwargs)
  File "/home/mike/Desktop/microblog-0.15/app/main/routes.py", line 41, in index
    page, current_app.config['25'], False)
KeyError: '25'
2019-09-20 16:52:02,661 ERROR: Exception on /explore [GET] [in /home/mike/Desktop/microblog-0.15/venv/lib/python3.6/site-packages/flask/app.py:1761]
Traceback (most recent call last):
  File "/home/mike/Desktop/microblog-0.15/venv/lib/python3.6/site-packages/flask/app.py", line 2292, in wsgi_app
    response = self.full_dispatch_request()
  File "/home/mike/Desktop/microblog-0.15/venv/lib/python3.6/site-packages/flask/app.py", line 1815, in full_dispatch_request
    rv = self.handle_user_exception(e)
  File "/home/mike/Desktop/microblog-0.15/venv/lib/python3.6/site-packages/flask/app.py", line 1718, in handle_user_exception
    reraise(exc_type, exc_value, tb)
  File "/home/mike/Desktop/microblog-0.15/venv/lib/python3.6/site-packages/flask/_compat.py", line 35, in reraise
    raise value
  File "/home/mike/Desktop/microblog-0.15/venv/lib/python3.6/site-packages/flask/app.py", line 1813, in full_dispatch_request
    rv = self.dispatch_request()
  File "/home/mike/Desktop/microblog-0.15/venv/lib/python3.6/site-packages/flask/app.py", line 1799, in dispatch_request
    return self.view_functions[rule.endpoint](**req.view_args)
  File "/home/mike/Desktop/microblog-0.15/venv/lib/python3.6/site-packages/flask_login/utils.py", line 228, in decorated_view
    return func(*args, **kwargs)
  File "/home/mike/Desktop/microblog-0.15/app/main/routes.py", line 56, in explore
    page, current_app.config['25'], False)@bp.route('/search')
KeyError: '25'
2019-09-20 16:52:03,256 ERROR: Exception on /index [GET] [in /home/mike/Desktop/microblog-0.15/venv/lib/python3.6/site-packages/flask/app.py:1761]
Traceback (most recent call last):
  File "/home/mike/Desktop/microblog-0.15/venv/lib/python3.6/site-packages/flask/app.py", line 2292, in wsgi_app
    response = self.full_dispatch_request()
  File "/home/mike/Desktop/microblog-0.15/venv/lib/python3.6/site-packages/flask/app.py", line 1815, in full_dispatch_request
    rv = self.handle_user_exception(e)
  File "/home/mike/Desktop/microblog-0.15/venv/lib/python3.6/site-packages/flask/app.py", line 1718, in handle_user_exception
    reraise(exc_type, exc_value, tb)
  File "/home/mike/Desktop/microblog-0.15/venv/lib/python3.6/site-packages/flask/_compat.py", line 35, in reraise
    raise value
  File "/home/mike/Desktop/microblog-0.15/venv/lib/python3.6/site-packages/flask/app.py", line 1813, in full_dispatch_request
    rv = self.dispatch_request()
  File "/home/mike/Desktop/microblog-0.15/venv/lib/python3.6/site-packages/flask/app.py", line 1799, in dispatch_request
    return self.view_functions[rule.endpoint](**req.view_args)
  File "/home/mike/Desktop/microblog-0.15/venv/lib/python3.6/site-packages/flask_login/utils.py", line 228, in decorated_view
    return func(*args, **kwargs)
  File "/home/mike/Desktop/microblog-0.15/app/main/routes.py", line 41, in index
    page, current_app.config['25'], False)
KeyError: '25'
